<?xml version="1.0"?>
<robot xmlns:xacro="http://www.ros.org/wiki/xacro">
 <xacro:macro name="link_wheel" params="name">
        <link name="${name}">
            <inertial>
              <mass value="5"/>
              <origin rpy="0 1.5707 1.5707" xyz="0 0 0"/>
              <inertia ixx="${(3*0.085*0.085+0.055*0.03)/12}" ixy="0" ixz="0" iyy="${(3*0.085*0.085+0.03*0.03)/12}" iyz="0" izz="${(0.085*0.085)/2}"/>
            </inertial>
            <collision name="link_right_wheel_collision">
              <origin rpy="0 1.5707 1.5707" xyz="0.0 0 0"/>
              <geometry>
              <cylinder radius="0.085" length="0.03"/>-->
               <!-- <mesh filename="package://m2wr_description/meshes/Wheel.dae"  scale="0.0035 0.0035 0.0035"/>-->
              = </geometry>
            </collision>
            <visual name="${name}_visual">
              <origin rpy="0 1.5707 1.5707" xyz="0.0 0 0"/>
              <geometry> 
              <cylinder radius="0.085" length="0.03"/>
               <!-- <mesh filename="package://m2wr_description/meshes/Wheel.dae"  scale="0.0035 0.0035 0.0035"/> -->
      
              </geometry>
            </visual>
        </link> 
    </xacro:macro>
   
    <xacro:macro name="joint_wheel" params="name child origin_xyz">
      <joint name="${name}" type="continuous">
        <origin rpy="0 0 0" xyz="${origin_xyz}"/>
        <child link="${child}"/>
        <parent link="link_chassis"/>
        <axis rpy="0 0 0" xyz="0 1 0"/>
        <limit effort="10000" velocity="1000"/>
        <joint_properties damping="0" friction="0"/>
      </joint>
    </xacro:macro>
    
    <xacro:macro name="cylinder_inertia" params="mass r l">
      <inertia  ixx="${mass*(3*r*r+l*l)/12}" ixy = "0" ixz = "0"
                iyy="${mass*(3*r*r+l*l)/12}" iyz = "0"
                izz="${mass*(r*r)/2}" />
    </xacro:macro>
</robot>
